使用multiprocess时，如果内部出错，他不会报错，同时也不会停止，而且有可能卡很长时间也停不下来。

解决方法，对于每个单个任务使用try except，然后通过traceback打印报错，这样就能看到错误信息了

```python
import traceback

try:
    xxxx
except Exception as e:
    print(traceback.format_exc())
    print(f'Error: {e}')
```